2022-01-01 12:51:09,644 INFO: Initialized curve data.
2022-01-01 12:51:09,647 INFO: Setting up initial twist data...
2022-01-01 12:51:10,622 INFO: Twist setup complete.
2022-01-01 12:51:10,622 INFO: Searching for rational points on each twist...
2022-01-01 12:51:11,519 INFO: Finished searching for rational points on each twist.
2022-01-01 12:51:11,519 INFO: Testing local solvability of twists...
2022-01-01 12:51:18,095 INFO: Finished local solvability testing.
2022-01-01 12:51:18,098 INFO: Computing elliptic curve a-invariants...
2022-01-01 12:51:28,736 INFO: Finished computation of a-invariants.
2022-01-01 12:51:28,738 INFO: Computing MW group (delta = ['1'], g = [12, 16, -20, -16, 0, 1])...
2022-01-01 12:55:23,391 INFO: Finished MW computation (delta = ['1'], g = [12, 16, -20, -16, 0, 1])
2022-01-01 12:55:23,395 INFO: Skipped MW computation because no base point (delta = ['-12', '-15', '18', '15', '0', '-1'])
2022-01-01 12:55:23,396 INFO: Computing MW group (delta = ['12', '15', '-20', '-16', '0', '1'], g = [12, 16, -20, -16, 0, 1])...
2022-01-01 12:57:29,548 INFO: Finished MW computation (delta = ['12', '15', '-20', '-16', '0', '1'], g = [12, 16, -20, -16, 0, 1])
2022-01-01 12:57:29,554 INFO: Computing MW group (delta = ['-1', '2', '1'], g = [12, 16, -20, -16, 0, 1])...
2022-01-01 13:43:52,067 ERROR: An exception occurred. Recording data and exiting.
Traceback (most recent call last):
  File "/project/arithgeo/drhast/twocover-descent/./twocover-processor.sage.py", line 506, in <module>
    rank, MW_proven, orders, gens = twist_MW_group(D)
  File "/project/arithgeo/drhast/twocover-descent/./twocover-processor.sage.py", line 327, in twist_MW_group
    A, mw, bool_rank, bool_index = magma.MordellWeilGroup(E, nvals=_sage_const_4 )
  File "/share/pkg.7/sagemath/9.3/install/lib/python3.9/site-packages/sage/interfaces/magma.py", line 1787, in __call__
    return M.function_call(self._name,
  File "/share/pkg.7/sagemath/9.3/install/lib/python3.9/site-packages/sage/interfaces/magma.py", line 1162, in function_call
    return self._do_call(fun, nvals)
  File "/share/pkg.7/sagemath/9.3/install/lib/python3.9/site-packages/sage/interfaces/magma.py", line 1221, in _do_call
    raise TypeError("Error executing Magma code:\n%s" % out)
TypeError: Error executing Magma code:

Current total memory usage: 8182.7MB, failed memory request: 32.0MB
System Error: User memory limit has been reached
2022-01-03 13:14:57,000 INFO: Obsolete "loc_solv_error" keys removed.
