2022-01-12 09:25:16,470 INFO: Initialized curve data.
2022-01-12 09:25:16,473 INFO: Setting up initial twist data...
2022-01-12 09:25:17,867 INFO: Twist setup complete.
2022-01-12 09:25:17,867 INFO: Searching for rational points on each twist...
2022-01-12 09:25:19,348 INFO: Finished searching for rational points on each twist.
2022-01-12 09:25:19,348 INFO: Testing local solvability of twists...
2022-01-12 09:25:22,803 INFO: Finished local solvability testing.
2022-01-12 09:25:22,806 INFO: Computing elliptic curve a-invariants...
2022-01-12 09:25:27,979 INFO: Finished computation of a-invariants.
2022-01-12 09:25:27,981 INFO: Skipped MW computation because no base point (delta = ['-1/2', '1/2', '1'])
2022-01-12 09:25:27,981 INFO: Computing MW group (delta = ['1/4', '-1/4', '-1', '1/2', '1'], g = [4, 0, -20, -7, 28, 20])...
2022-01-12 09:26:25,745 INFO: Finished MW computation (delta = ['1/4', '-1/4', '-1', '1/2', '1'], g = [4, 0, -20, -7, 28, 20])
2022-01-12 09:26:25,749 INFO: Computing MW group (delta = ['-1/2', '0', '1'], g = [4, 0, -20, -7, 28, 20])...
2022-01-12 09:29:10,514 INFO: Finished MW computation (delta = ['-1/2', '0', '1'], g = [4, 0, -20, -7, 28, 20])
2022-01-12 09:29:10,518 INFO: Computing MW group (delta = ['1'], g = [4, 0, -20, -7, 28, 20])...
2022-01-12 11:23:54,005 ERROR: An exception occurred. Recording data and exiting.
Traceback (most recent call last):
  File "/project/arithgeo/drhast/twocover-descent/./twocover-processor.sage.py", line 506, in <module>
    rank, MW_proven, orders, gens = twist_MW_group(D)
  File "/project/arithgeo/drhast/twocover-descent/./twocover-processor.sage.py", line 329, in twist_MW_group
    A, mw, bool_rank, bool_index = magma.MordellWeilGroup(E, nvals=_sage_const_4 )
  File "/share/pkg.7/sagemath/9.3/install/lib/python3.9/site-packages/sage/interfaces/magma.py", line 1787, in __call__
    return M.function_call(self._name,
  File "/share/pkg.7/sagemath/9.3/install/lib/python3.9/site-packages/sage/interfaces/magma.py", line 1162, in function_call
    return self._do_call(fun, nvals)
  File "/share/pkg.7/sagemath/9.3/install/lib/python3.9/site-packages/sage/interfaces/magma.py", line 1221, in _do_call
    raise TypeError("Error executing Magma code:\n%s" % out)
TypeError: Error executing Magma code:

Current total memory usage: 16359.8MB, failed memory request: 32.0MB
System Error: User memory limit has been reached
